Workbook

Sheet Sales Contract
A1: 销售合同 SALES CONTRACT
D3: 合同号 Contract No.:
D4: 合同日期: CONTRACT DATE:
A7: 卖方 SELLER: | B7: 北京鸿坤环宇贸易咨询有限责任公司 HK Global Trade Consulting LLC
A8: 地址 ADDRESS: | B8: 北京西城区西直门外大街18号楼14层1单元 1708Add: No.18 Xizhimenwai Street 14th Floor Unit 1708,
B9: Xicheng District, Beijing, China 100044
A11: 买方 BUYER:
A12: 地址 ADDRESS:
A13: ATTN:
A14: TEL:
A16: 买卖双方同意成交下列商品签订条款如下：
A17: The undersigned Sellers and Buyers have agreed to close the following transactions according tothe terms and conditions stipulated below:
A19: NUMBER | B19: DESCRIPTION OF GOODS | C19: QUANTITY | D19: UNIT | E19: UNIT PRICE | F19: TOTAL AMOUNT | G19: 单价RMB | H19: 总价RMB | I19: 含税人民币汇总 | J19: 汇率 | K19: 请给出利润点 | L19: FOB单价 （报关单价USD） | M19: FOB总价 （报关总价USD）
A20: 1 | E20: =L20 | F20: =M20 | G20: =I20/C20 | I20: =H20*$H$18 | L20: =ROUND(G20/J20*K20,2) | M20: =L20*C20
A21: 2 | E21: =L21 | F21: =M21 | G21: =I21/C21 | I21: =H21*$H$18 | L21: =ROUND(G21/J21*K21,2) | M21: =L21*C21
A22: 3 | E22: =L22 | F22: =M22 | G22: =I22/C22 | I22: =H22*$H$18 | L22: =ROUND(G22/J22*K22,2) | M22: =L22*C22
A23: 4 | E23: =L23 | F23: =M23 | G23: =I23/C23 | I23: =H23*$H$18 | L23: =ROUND(G23/J23*K23,2) | M23: =L23*C23
A24: 5 | E24: =L24 | F24: =M24 | G24: =I24/C24 | I24: =H24*$H$18 | L24: =ROUND(G24/J24*K24,2) | M24: =L24*C24
A25: 6 | E25: =L25 | F25: =M25 | G25: =I25/C25 | I25: =H25*$H$18 | L25: =ROUND(G25/J25*K25,2) | M25: =L25*C25
A26: 7 | E26: =L26 | F26: =M26 | G26: =I26/C26 | I26: =H26*$H$18 | L26: =ROUND(G26/J26*K26,2) | M26: =L26*C26
A27: 8 | E27: =L27 | F27: =M27 | G27: =I27/C27 | I27: =H27*$H$18 | L27: =ROUND(G27/J27*K27,2) | M27: =L27*C27
A28: 9 | E28: =L28 | F28: =M28 | G28: =I28/C28 | I28: =H28*$H$18 | L28: =ROUND(G28/J28*K28,2) | M28: =L28*C28
A29: 10 | E29: =L29 | F29: =M29 | G29: =I29/C29 | I29: =H29*$H$18 | L29: =ROUND(G29/J29*K29,2) | M29: =L29*C29
A30: 11 | E30: =L30 | F30: =M30 | G30: =I30/C30 | I30: =H30*$H$18 | L30: =ROUND(G30/J30*K30,2) | M30: =L30*C30
A31: 12 | E31: =L31 | F31: =M31 | G31: =I31/C31 | I31: =H31*$H$18 | L31: =ROUND(G31/J31*K31,2) | M31: =L31*C31
... A79: 60 | E79: =L79 | F79: =M79 | G79: =I79/C79 | I79: =H79*$H$18 | L79: =ROUND(G79/J79*K79,2) | M79: =L79*C79
A80: TOTAL | F80: =SUM(F20:F79) | H80: =SUM(H20:H79) | I80: =SUM(I20:I79) | M80: =SUM(M20:M79)
A82: 1. 付款条件 | B82: Payment Terms: 100% payment by T/T. | J82: 江总说床垫款项先不付，暂时不算成本，先发货；
A83: 2. 装运时间 | B83: Delivery Time: Within 35-40 days after receive payment.
A84: 3. 装运口岸
A85: 4. 目的港口 | G85: 此批次发货汇总 | J85: 6.8167 | K85: 1.02
A86: 5. 成交方式 | B86: Trade Terms: FOB YANTIAN, CHINA
A87: 6. 备注 | B87: Remarks: N/A
A89: (1) 品质数量异议:如买方提出索赔,凡属品质异议须于货到目的港口之日起三个月内提出; 凡属数量异议须于货到目的港口之日起一周内提出, 对所装运货物所提任何异议属于保险公司或轮船公司以及其他有关运输机构或邮递机构所负责者, 售方将不负任何责任. In case of quality discrepancy, claim should be filed by the buyers within 3 months after the arrival of the goods at the port of destination, while of quantity discrepancy, claim should be filed by the buyers within 7 days after the arrival of the goods at the port of destination. It is understood that the Sellers shall not be liable for any discrepancy of the goods shipped due to causes for which Insurance Company, Shipping Company, other transportation, organization or Post Office are liable.
H90: 总金额 | I90: 837782
A91: (2) 本合同所述全部或部分商品,如因人力不可抗拒的原因,以致不能履约或延迟交货,售方 概不负责. The Sellers shall not be held liable for failure or delay in delivery of the entire lot or a portion of the goods under this Sales Contract on consequence ofany Force Major incidents. | H91: 床垫总金额 | I91: 84750
H92: 30%预付款 | I92: =837782*0.3 -> 251334.6
A93: (3) 仲裁: 凡因执行本合同或于本合同有关事项所发生的一切争执,应由双方通过友好协商解决. 如果不能协商解决时, 则在被告国家根据被告仲裁机构的仲裁程序规则进行仲裁.仲裁决定是终局的,对双方具有同等的约束力.仲裁费用除非仲裁机构另有决定外, 均由败诉一方负担. Arbitration: All disputes in connection with this Contract or the execution thereof shall be settled by negotiation between two parties. If no settlement can be reached, the case in dispute shall then be submitted for arbitration in the country of defendant in accordance with the arbitration regulation of the arbitration organization of the defendant country. The decision made by the arbitration organization shall be taken as final and binding upon both parties. The arbitration expenses shall be borne by the losing party unless otherwise awarded by the arbitration. | H93: 沙发尾款 | I93: 78750
H94: 尾款 | I94: =I46-I47-I48-I49 -> 422947.4
A95: (4) 买方收到本合同后立即签字盖章确认,如买方对本合同有异议,应于收到后一个工作日提出, 否则卖方认为买方已同意本合同所规定的各项条款. The buyers are requested to sign and stamp on it and return one copy of this Sales Contract immediately after receipt of the same. Objection, if any, should be raise by the Buyers within one working day after the receipt of this Sales Contract, in the absence of which it is understood that the Buyers have accepted the terms and conditions ofthe Sales Contract.
...

Sheet Template_CI
A1: HK GLOBAL TRADE CONSULTING LLC
A2: 北京鸿坤环宇贸易咨询有限责任公司
A3: No.18 Xizhimenwai Street 14th Floor Unit 1708,
A4: Xicheng District, Beijing, China 100044
A5: 北京西城区西直门外大街18号楼14层1单元
A6: TEL: 010-6225-8188
A7: www.hongkunglobal.com
A9: COMMERCIAL INVOICE
A11: BUYER: | B11: ='Sales Contract'!B11 -> CSQUARE STEEL CO., LIMITED | D11: INV#: | E11: ='Sales Contract'!E3 -> HKG26-024-B5&005-B4
A12: ADD: | B12: Room 101A, 1/F., GenplasIndustrial Building, 56 Hoi YuenRoad, | D12: DATE:
B13: Kwun Tong, HONG KONG
A14: ATTN: | B14: Zhao Haoyuan
A15: TEL: | B15: +852 3050 1949
A19: NUMBER | B19: DESCRIPTION OF GOODS | C19: QUANTITY | D19: UNIT | E19: UNIT PRICE | F19: TOTAL
A20: 1 | B20: ='Sales Contract'!B20 | C20: ='Sales Contract'!C20 | D20: ='Sales Contract'!D20 | E20: ='Sales Contract'!E20 | F20: ='Sales Contract'!F20
A21: 2 | B21: ='Sales Contract'!B21 | C21: ='Sales Contract'!C21 | D21: ='Sales Contract'!D21 | E21: ='Sales Contract'!E21 | F21: ='Sales Contract'!F21
A22: 3 | B22: ='Sales Contract'!B22 | C22: ='Sales Contract'!C22 | D22: ='Sales Contract'!D22 | E22: ='Sales Contract'!E22 | F22: ='Sales Contract'!F22
A23: 4 | B23: ='Sales Contract'!B23 | C23: ='Sales Contract'!C23 | D23: ='Sales Contract'!D23 | E23: ='Sales Contract'!E23 | F23: ='Sales Contract'!F23
A24: 5 | B24: ='Sales Contract'!B24 | C24: ='Sales Contract'!C24 | D24: ='Sales Contract'!D24 | E24: ='Sales Contract'!E24 | F24: ='Sales Contract'!F24
A25: 6 | B25: ='Sales Contract'!B25 | C25: ='Sales Contract'!C25 | D25: ='Sales Contract'!D25 | E25: ='Sales Contract'!E25 | F25: ='Sales Contract'!F25
A26: 7 | B26: ='Sales Contract'!B26 | C26: ='Sales Contract'!C26 | D26: ='Sales Contract'!D26 | E26: ='Sales Contract'!E26 | F26: ='Sales Contract'!F26
A27: 8 | B27: ='Sales Contract'!B27 | C27: ='Sales Contract'!C27 | D27: ='Sales Contract'!D27 | E27: ='Sales Contract'!E27 | F27: ='Sales Contract'!F27
A28: 9 | B28: ='Sales Contract'!B28 | C28: ='Sales Contract'!C28 | D28: ='Sales Contract'!D28 | E28: ='Sales Contract'!E28 | F28: ='Sales Contract'!F28
A29: 10 | B29: ='Sales Contract'!B29 | C29: ='Sales Contract'!C29 | D29: ='Sales Contract'!D29 | E29: ='Sales Contract'!E29 | F29: ='Sales Contract'!F29
A30: 11 | B30: ='Sales Contract'!B30 | C30: ='Sales Contract'!C30 | D30: ='Sales Contract'!D30 | E30: ='Sales Contract'!E30 | F30: ='Sales Contract'!F30
A31: 12 | B31: ='Sales Contract'!B31 | C31: ='Sales Contract'!C31 | D31: ='Sales Contract'!D31 | E31: ='Sales Contract'!E31 | F31: ='Sales Contract'!F31
... A79: 60 | B79: ='Sales Contract'!B79 | C79: ='Sales Contract'!C79 | D79: ='Sales Contract'!D79 | E79: ='Sales Contract'!E79 | F79: ='Sales Contract'!F79
A80: TOTAL | F80: =SUM(F20:F79)
A89: HK GLOBAL TRADE CONSULTING LLC
C90: 北京鸿坤环宇贸易咨询有限责任公司
A91: No.18 Xizhimenwai Street 14th Floor Unit 1708, Xicheng District, Beijing, China 100044
A92: 北京西城区西直门外大街18号楼14层1单元

Sheet Template_PL
A1: HK GLOBAL TRADE CONSULTING LLC
A3: No.18 Xizhimenwai Street 14th Floor Unit 1708,
A4: Xicheng District, Beijing, China 100044
A5: TEL: 010-6225-8188
A6: www.hongkunglobal.com
A8: PACKING LIST
A10: BUYER: | E10: INV#: | F10: =Template_CI!E11 -> HKG26-024-B5&005-B4
A11: ATTN: | B11: Zhao Haoyuan | E11: DATE: | F11: 46204
A12: COMPANY: | B12: =Template_CI!B11 -> CSQUARE STEEL CO., LIMITED
A13: ADD: | B13: Room 101A, 1/F., GenplasIndustrial Building, 56 Hoi YuenRoad,
B14: Kwun Tong, HONG KONG
A15: TEL: | B15: +852 3050 1949
A19: NUMBER | B19: DESCRIPTION OF GOODS | C19: QUANTITY (UNIT) | D19: PACKAGES | E19: G/W (KG) | F19: N/W (KG) | G19: VOLUME (CBM)
A20: 1 | B20: ='Sales Contract'!B20 | C20: ='Sales Contract'!C20&" "&'Sales Contract'!D20
A21: 2 | B21: ='Sales Contract'!B21 | C21: ='Sales Contract'!C21&" "&'Sales Contract'!D21
A22: 3 | B22: ='Sales Contract'!B22 | C22: ='Sales Contract'!C22&" "&'Sales Contract'!D22
A23: 4 | B23: ='Sales Contract'!B23 | C23: ='Sales Contract'!C23&" "&'Sales Contract'!D23
A24: 5 | B24: ='Sales Contract'!B24 | C24: ='Sales Contract'!C24&" "&'Sales Contract'!D24
A25: 6 | B25: ='Sales Contract'!B25 | C25: ='Sales Contract'!C25&" "&'Sales Contract'!D25
A26: 7 | B26: ='Sales Contract'!B26 | C26: ='Sales Contract'!C26&" "&'Sales Contract'!D26
A27: 8 | B27: ='Sales Contract'!B27 | C27: ='Sales Contract'!C27&" "&'Sales Contract'!D27
A28: 9 | B28: ='Sales Contract'!B28 | C28: ='Sales Contract'!C28&" "&'Sales Contract'!D28
A29: 10 | B29: ='Sales Contract'!B29 | C29: ='Sales Contract'!C29&" "&'Sales Contract'!D29
A30: 11 | B30: ='Sales Contract'!B30 | C30: ='Sales Contract'!C30&" "&'Sales Contract'!D30
A31: 12 | B31: ='Sales Contract'!B31 | C31: ='Sales Contract'!C31&" "&'Sales Contract'!D31
... A79: 60 | B79: ='Sales Contract'!B79 | C79: ='Sales Contract'!C79&" "&'Sales Contract'!D79
A80: TOTAL | D80: =SUM(D20:D79) | E80: =SUM(E20:E79) | F80: =SUM(F20:F79) | G80: =SUM(G20:G79)
A95: HK GLOBAL TRADE CONSULTING LLC
A96: No.18 Xizhimenwai Street 14th Floor Unit 1708, Xicheng District, Beijing, China 100044

Sheet 报关单及申报要素
A3: 中华人民共和国海关出口货物报关单
A5: 预录入编号： | C5: 海关编号： | G5: （XX海关） | O5: 页码/页数:
A7: 境内发货人 | D7: 出境关别 | G7: 出口日期 | L7: 申报日期 | N7: 备案号
A8: 北京鸿坤环宇贸易咨询有限责任公司
A9: 境外收货人 | D9: 运输方式 | G9: 运输工具名称及航次号 | L9: 提运单号
A10: ='Sales Contract'!B11 -> CSQUARE STEEL CO., LIMITED | D10: 水路运输
A11: 生产销售单位 | D11: 监管方式 | G11: 征免性质 | L11: 许可证号
A12: 北京鸿坤环宇贸易咨询有限责任公司 | D12: 一般贸易 | G12: 一般征税
A13: 合同协议号 | D13: 贸易国（地区） | G13: 运抵国（地区） | L13: 指运港 | N13: 离境口岸
A14: ='Sales Contract'!E3 -> HKG26-024-B5&005-B4
A15: 包装种类 | D15: 件数 | E15: 毛重（千克） | G15: 净重（千克） | J15: 成交方式 | L15: 运费 | M15: 保费 | O15: 杂费
A16: 其他包装 99 | D16: =Template_PL!D36 -> 557 | E16: =Template_PL!E36 -> 15067 | G16: =Template_PL!F36 -> 14122 | J16: FOB
A17: 随附单证及编号
A19: 标记唛码及备注
A21: 项号 | B21: 商品编号 | C21: 商品名称及规格型号 | E21: 数量及单位 | G21: 净重（千克） | I21: 单价/总价/币制 | L21: 原产国 （地区） | M21: 最终目的国 （地区） | N21: 境内货源地 | O21: 征免
A22: 1 | E22: ='Sales Contract'!C20 | G22: =Template_PL!F20 | H22: KG | I22: ='Sales Contract'!E20 | J22: =I22*E22 | K22: USD
A23: 2 | E23: ='Sales Contract'!C21 | G23: =Template_PL!F21 | H23: KG | I23: ='Sales Contract'!E21 | J23: =I23*E23 | K23: USD
A24: 3 | E24: ='Sales Contract'!C22 | G24: =Template_PL!F22 | H24: KG | I24: ='Sales Contract'!E22 | J24: =I24*E24 | K24: USD
A25: 4 | E25: ='Sales Contract'!C23 | G25: =Template_PL!F23 | H25: KG | I25: ='Sales Contract'!E23 | J25: =I25*E25 | K25: USD
A26: 5 | E26: ='Sales Contract'!C24 | G26: =Template_PL!F24 | H26: KG | I26: ='Sales Contract'!E24 | J26: =I26*E26 | K26: USD
A27: 6 | E27: ='Sales Contract'!C25 | G27: =Template_PL!F25 | H27: KG | I27: ='Sales Contract'!E25 | J27: =I27*E27 | K27: USD
A28: 7 | E28: ='Sales Contract'!C26 | G28: =Template_PL!F26 | H28: KG | I28: ='Sales Contract'!E26 | J28: =I28*E28 | K28: USD
A29: 8 | E29: ='Sales Contract'!C27 | G29: =Template_PL!F27 | H29: KG | I29: ='Sales Contract'!E27 | J29: =I29*E29 | K29: USD
A30: 9 | E30: ='Sales Contract'!C28 | G30: =Template_PL!F28 | H30: KG | I30: ='Sales Contract'!E28 | J30: =I30*E30 | K30: USD
A31: 10 | E31: ='Sales Contract'!C29 | G31: =Template_PL!F29 | H31: KG | I31: ='Sales Contract'!E29 | J31: =I31*E31 | K31: USD
A32: 11 | E32: ='Sales Contract'!C30 | G32: =Template_PL!F30 | H32: KG | I32: ='Sales Contract'!E30 | J32: =I32*E32 | K32: USD
A33: 12 | E33: ='Sales Contract'!C31 | G33: =Template_PL!F31 | H33: KG | I33: ='Sales Contract'!E31 | J33: =I33*E33 | K33: USD
... A81: 60 | E81: ='Sales Contract'!C79 | G81: =Template_PL!F79 | H81: KG | I81: ='Sales Contract'!E79 | J81: =I81*E81 | K81: USD
G89: =SUM(G22:G81) | J89: =SUM(J22:J81)
A90: 报关人员 | C90: 电话 | D90: 兹声明以上内容承担如实申报、依法纳税之法律责任 | L90: 海关批注及签章
A92: 申报单位 | D92: 申请单位(签章)
C94: 品名 | D94: 申报要素
A95: 1
A96: 2
A97: 3
A98: 4
A99: 5
A100: 6
A101: 7
A102: 8
...
